const x = 1;

try{
    x=2;
} catch(err) {
    console.log(`Error: ${err}`);
}